mplus_output/uni-29-CHARLS_W1.out
Mplus VERSION 8.1 (Mac)
MUTHEN & MUTHEN
04/23/2020  10:56 PM

INPUT INSTRUCTIONS

  DATA:
  FILE = "uni-29-CHARLS_W1.dat";

  VARIABLE:
  NAMES = mplusid UDAT UDAY UMON UYER UIWR UDWR UFCO USEA USUB;
   MISSING=.;
   CATEGORICAL ARE all; idvariable = mplusid;
  ANALYSIS:
  estimator = wlsmv; coverage=0;
  MODEL:
  g by UDAT * ;
   g by UDAY * ;
   g by UMON * ;
   g by UYER * ;
   g by UIWR * ;
   g by UDWR * ;
   g by USUB * ;
   g by UFCO * ;
   g by USEA * ;
   g @ 1;

  OUTPUT:
  standardized; svalues;



INPUT READING TERMINATED NORMALLY




SUMMARY OF ANALYSIS

Number of groups                                                 1
Number of observations                                       16043

Number of dependent variables                                    9
Number of independent variables                                  0
Number of continuous latent variables                            1

Observed dependent variables

  Binary and ordered categorical (ordinal)
   UDAT        UDAY        UMON        UYER        UIWR        UDWR
   UFCO        USEA        USUB

Continuous latent variables
   G

Variables with special functions

  ID variable           MPLUSID

Estimator                                                    WLSMV
Maximum number of iterations                                  1000
Convergence criterion                                    0.500D-04
Maximum number of steepest descent iterations                   20
Maximum number of iterations for H1                           2000
Convergence criterion for H1                             0.100D-03
Parameterization                                             DELTA
Link                                                        PROBIT

Input data file(s)
  uni-29-CHARLS_W1.dat

Input data format  FREE


SUMMARY OF DATA

     Number of missing data patterns            93


COVARIANCE COVERAGE OF DATA

Minimum covariance coverage value   0.000


     PROPORTION OF DATA PRESENT


           Covariance Coverage
              UDAT          UDAY          UMON          UYER          UIWR
              ________      ________      ________      ________      ________
 UDAT           0.898
 UDAY           0.798         0.844
 UMON           0.898         0.798         0.898
 UYER           0.898         0.798         0.898         0.898
 UIWR           0.810         0.756         0.810         0.810         0.885
 UDWR           0.804         0.751         0.804         0.804         0.873
 UFCO           0.888         0.834         0.888         0.888         0.877
 USEA           0.872         0.826         0.872         0.872         0.846
 USUB           0.831         0.772         0.831         0.831         0.813


           Covariance Coverage
              UDWR          UFCO          USEA          USUB
              ________      ________      ________      ________
 UDWR           0.878
 UFCO           0.871         0.987
 USEA           0.840         0.936         0.947
 USUB           0.806         0.883         0.858         0.890


UNIVARIATE PROPORTIONS AND COUNTS FOR CATEGORICAL VARIABLES

    UDAT
      Category 1    0.189         2722.000
      Category 2    0.811        11679.000
    UDAY
      Category 1    0.314         4255.000
      Category 2    0.686         9282.000
    UMON
      Category 1    0.061          875.000
      Category 2    0.939        13526.000
    UYER
      Category 1    0.197         2832.000
      Category 2    0.803        11569.000
    UIWR
      Category 1    0.014          200.000
      Category 2    0.048          678.000
      Category 3    0.109         1555.000
      Category 4    0.195         2774.000
      Category 5    0.243         3446.000
      Category 6    0.315         4471.000
      Category 7    0.051          731.000
      Category 8    0.018          257.000
      Category 9    0.004           61.000
      Category 10    0.002           30.000
    UDWR
      Category 1    0.136         1915.000
      Category 2    0.074         1036.000
      Category 3    0.154         2170.000
      Category 4    0.202         2850.000
      Category 5    0.193         2718.000
      Category 6    0.197         2780.000
      Category 7    0.027          386.000
      Category 8    0.011          152.000
      Category 9    0.004           56.000
      Category 10    0.001           19.000
    UFCO
      Category 1    0.368         5824.000
      Category 2    0.632        10004.000
    USEA
      Category 1    0.109         1654.000
      Category 2    0.891        13543.000
    USUB
      Category 1    0.052          748.000
      Category 2    0.135         1927.000
      Category 3    0.081         1157.000
      Category 4    0.121         1734.000
      Category 5    0.180         2564.000
      Category 6    0.431         6153.000



THE MODEL ESTIMATION TERMINATED NORMALLY



MODEL FIT INFORMATION

Number of Free Parameters                       38

Chi-Square Test of Model Fit

          Value                           5050.188*
          Degrees of Freedom                    27
          P-Value                           0.0000

*   The chi-square value for MLM, MLMV, MLR, ULSMV, WLSM and WLSMV cannot be used
    for chi-square difference testing in the regular way.  MLM, MLR and WLSM
    chi-square difference testing is described on the Mplus website.  MLMV, WLSMV,
    and ULSMV difference testing is done using the DIFFTEST option.

RMSEA (Root Mean Square Error Of Approximation)

          Estimate                           0.108
          90 Percent C.I.                    0.105  0.110
          Probability RMSEA <= .05           0.000

CFI/TLI

          CFI                                0.903
          TLI                                0.871

Chi-Square Test of Model Fit for the Baseline Model

          Value                          51925.028
          Degrees of Freedom                    36
          P-Value                           0.0000

SRMR (Standardized Root Mean Square Residual)

          Value                              0.100

Optimum Function Value for Weighted Least-Squares Estimator

          Value                     0.13319513D+00



MODEL RESULTS

                                                    Two-Tailed
                    Estimate       S.E.  Est./S.E.    P-Value

 G        BY
    UDAT               0.399      0.012     33.518      0.000
    UDAY               0.480      0.011     44.518      0.000
    UMON               0.491      0.015     33.222      0.000
    UYER               0.532      0.011     48.985      0.000
    UIWR               0.830      0.005    154.438      0.000
    UDWR               0.814      0.005    149.703      0.000
    USUB               0.534      0.008     69.385      0.000
    UFCO               0.609      0.009     71.579      0.000
    USEA               0.531      0.013     41.092      0.000

 Thresholds
    UDAT$1            -0.882      0.012    -73.088      0.000
    UDAY$1            -0.484      0.011    -43.018      0.000
    UMON$1            -1.548      0.017    -93.576      0.000
    UYER$1            -0.854      0.012    -71.424      0.000
    UIWR$1            -2.195      0.028    -79.627      0.000
    UIWR$2            -1.540      0.017    -92.908      0.000
    UIWR$3            -0.949      0.012    -76.335      0.000
    UIWR$4            -0.341      0.011    -31.731      0.000
    UIWR$5             0.277      0.011     26.005      0.000
    UIWR$6             1.433      0.016     92.122      0.000
    UIWR$7             1.969      0.023     87.205      0.000
    UIWR$8             2.489      0.037     66.994      0.000
    UIWR$9             2.861      0.058     49.477      0.000
    UDWR$1            -1.099      0.013    -82.984      0.000
    UDWR$2            -0.808      0.012    -67.809      0.000
    UDWR$3            -0.349      0.011    -32.293      0.000
    UDWR$4             0.166      0.011     15.667      0.000
    UDWR$5             0.703      0.012     60.795      0.000
