mplus_output/uni-30-KLOSA_W1.out
Mplus VERSION 8.1 (Mac)
MUTHEN & MUTHEN
04/23/2020  10:56 PM

INPUT INSTRUCTIONS

  DATA:
  FILE = "uni-30-KLOSA_W1.dat";

  VARIABLE:
  NAMES = mplusid UDAY UDTS UPLC UADR UREG UDRG UNM7 UNM8 UREP2 UWRT UFCO USUB;
   MISSING=.;
   CATEGORICAL ARE all; idvariable = mplusid;
  ANALYSIS:
  estimator = wlsmv; coverage=0;
  MODEL:
  g by UDAY * ;
   g by USUB * ;
   g by UDTS * ;
   g by UFCO * ;
   g by UPLC * ;
   g by UADR * ;
   g by UREG * ;
   g by UDRG * ;
   g by UNM7 * ;
   g by UNM8 * ;
   g by UREP2 * ;
   g by UWRT * ;
   g @ 1;

  OUTPUT:
  standardized; svalues;



*** WARNING
  Data set contains cases with missing on all variables.
  These cases were not included in the analysis.
  Number of cases with missing on all variables:  213
   1 WARNING(S) FOUND IN THE INPUT INSTRUCTIONS




SUMMARY OF ANALYSIS

Number of groups                                                 1
Number of observations                                       10041

Number of dependent variables                                   12
Number of independent variables                                  0
Number of continuous latent variables                            1

Observed dependent variables

  Binary and ordered categorical (ordinal)
   UDAY        UDTS        UPLC        UADR        UREG        UDRG
   UNM7        UNM8        UREP2       UWRT        UFCO        USUB

Continuous latent variables
   G

Variables with special functions

  ID variable           MPLUSID

Estimator                                                    WLSMV
Maximum number of iterations                                  1000
Convergence criterion                                    0.500D-04
Maximum number of steepest descent iterations                   20
Maximum number of iterations for H1                           2000
Convergence criterion for H1                             0.100D-03
Parameterization                                             DELTA
Link                                                        PROBIT

Input data file(s)
  uni-30-KLOSA_W1.dat

Input data format  FREE


SUMMARY OF DATA

     Number of missing data patterns             1


COVARIANCE COVERAGE OF DATA

Minimum covariance coverage value   0.000


     PROPORTION OF DATA PRESENT


           Covariance Coverage
              UDAY          UDTS          UPLC          UADR          UREG
              ________      ________      ________      ________      ________
 UDAY           1.000
 UDTS           1.000         1.000
 UPLC           1.000         1.000         1.000
 UADR           1.000         1.000         1.000         1.000
 UREG           1.000         1.000         1.000         1.000         1.000
 UDRG           1.000         1.000         1.000         1.000         1.000
 UNM7           1.000         1.000         1.000         1.000         1.000
 UNM8           1.000         1.000         1.000         1.000         1.000
 UREP2          1.000         1.000         1.000         1.000         1.000
 UWRT           1.000         1.000         1.000         1.000         1.000
 UFCO           1.000         1.000         1.000         1.000         1.000
 USUB           1.000         1.000         1.000         1.000         1.000


           Covariance Coverage
              UDRG          UNM7          UNM8          UREP2         UWRT
              ________      ________      ________      ________      ________
 UDRG           1.000
 UNM7           1.000         1.000
 UNM8           1.000         1.000         1.000
 UREP2          1.000         1.000         1.000         1.000
 UWRT           1.000         1.000         1.000         1.000         1.000
 UFCO           1.000         1.000         1.000         1.000         1.000
 USUB           1.000         1.000         1.000         1.000         1.000


           Covariance Coverage
              UFCO          USUB
              ________      ________
 UFCO           1.000
 USUB           1.000         1.000


UNIVARIATE PROPORTIONS AND COUNTS FOR CATEGORICAL VARIABLES

    UDAY
      Category 1    0.058          582.000
      Category 2    0.942         9459.000
    UDTS
      Category 1    0.189         1895.000
      Category 2    0.811         8146.000
    UPLC
      Category 1    0.013          128.000
      Category 2    0.987         9913.000
    UADR
      Category 1    0.016          156.000
      Category 2    0.025          247.000
      Category 3    0.051          512.000
      Category 4    0.111         1110.000
      Category 5    0.798         8016.000
    UREG
      Category 1    0.029          291.000
      Category 2    0.048          484.000
      Category 3    0.119         1195.000
      Category 4    0.804         8071.000
    UDRG
      Category 1    0.117         1179.000
      Category 2    0.154         1550.000
      Category 3    0.294         2952.000
      Category 4    0.434         4360.000
    UNM7
      Category 1    0.010           99.000
      Category 2    0.990         9942.000
    UNM8
      Category 1    0.009           89.000
      Category 2    0.991         9952.000
    UREP2
      Category 1    0.035          355.000
      Category 2    0.965         9686.000
    UWRT
      Category 1    0.149         1494.000
      Category 2    0.851         8547.000
    UFCO
      Category 1    0.226         2271.000
      Category 2    0.774         7770.000
    USUB
      Category 1    0.113         1139.000
      Category 2    0.074          745.000
      Category 3    0.068          679.000
      Category 4    0.139         1394.000
      Category 5    0.144         1443.000
      Category 6    0.462         4641.000



THE MODEL ESTIMATION TERMINATED NORMALLY



MODEL FIT INFORMATION

Number of Free Parameters                       35

Chi-Square Test of Model Fit

          Value                           1260.069*
          Degrees of Freedom                    54
          P-Value                           0.0000

*   The chi-square value for MLM, MLMV, MLR, ULSMV, WLSM and WLSMV cannot be used
    for chi-square difference testing in the regular way.  MLM, MLR and WLSM
    chi-square difference testing is described on the Mplus website.  MLMV, WLSMV,
    and ULSMV difference testing is done using the DIFFTEST option.

RMSEA (Root Mean Square Error Of Approximation)

          Estimate                           0.047
          90 Percent C.I.                    0.045  0.049
          Probability RMSEA <= .05           0.980

CFI/TLI

          CFI                                0.980
          TLI                                0.975

Chi-Square Test of Model Fit for the Baseline Model

          Value                          59225.864
          Degrees of Freedom                    66
          P-Value                           0.0000

SRMR (Standardized Root Mean Square Residual)

          Value                              0.066

Optimum Function Value for Weighted Least-Squares Estimator

          Value                     0.56027847D-01



MODEL RESULTS

                                                    Two-Tailed
                    Estimate       S.E.  Est./S.E.    P-Value

 G        BY
    UDAY               0.825      0.012     71.320      0.000
    USUB               0.786      0.005    151.865      0.000
    UDTS               0.822      0.007    110.214      0.000
    UFCO               0.862      0.006    140.274      0.000
    UPLC               0.777      0.024     33.003      0.000
    UADR               0.786      0.007    104.851      0.000
    UREG               0.761      0.008     92.700      0.000
    UDRG               0.692      0.007     94.709      0.000
    UNM7               0.914      0.015     61.229      0.000
    UNM8               0.925      0.016     59.258      0.000
    UREP2              0.831      0.014     59.994      0.000
    UWRT               0.903      0.006    147.382      0.000

 Thresholds
    UDAY$1            -1.572      0.020    -78.161      0.000
